Workbook

Sheet 说明
A1: 物流团队绩效 V1 使用说明
A3: 一、月度流程
A4: 1 | B4: 月初：复制[打分表模板]并重命名为 打分-YYYY-MM（如 打分-2026-09）
A5: 2 | B5: 月初：在[任务块]登记每人3-5条当月任务+验收物，月份列填当月（如2026-09）
A6: 3 | B6: 月中：日常积累；数据不可得的指标，[数据可用]列选 NA
A7: 4 | B7: 月末：填打分表原始数据；任务块打分（0/50/100）
A8: 5 | B8: 出分：python -X utf8 scripts/build_kpi_dashboard.py --month YYYY-MM
A9: 二、得分公式
A10: 成本类 | B10: min(100, 100×目标÷实际单台)；单台=运费B÷数量A
A11: 达标率类 | B11: 达标单数÷总单数×100
A12: 上限类（缺货/退件/库龄等） | B12: 达标100；未达标 100×目标÷实际
A13: 下限类（准确率） | B13: 达标100；未达标 100×实际÷目标
A14: 请款类 | B14: 时间50%+金额50%；10号前=100，每迟1个工作日-20（下限0）；金额 min(100,占比÷90%×100)
A15: 三、降级规则（NA）
A16: 规则 | B16: 指标数据不可得→[数据可用]选NA→该指标剔除，个人总分按可用权重归一化；没数据不编分数
A17: 覆盖率 | B17: 打分表总分区显示每人 数据覆盖率=可用量化权重÷70；连续两月<60%的线，数据管道建设进该人下月任务块
A18: 四、可控性原则
A19: 原则 | B19: 计分指标必须本人可控；不可控但重要的（FOB截关装船准时率-货代控制）在打分表监控区只显示不计分
A20: 五、看板红绿灯
A21: 阈值 | B21: 绿≥85 / 黄70-84.9 / 红<70 / NA灰；实习生（张雨洁）算分但不排名不挂钱
A22: 六、版本
A23: V1 | B23: 2026-08-19 定稿；权重固定，2027-02 复盘

Sheet 人员与权重
A1: 团队分工与权重（固定，2027-02复盘调整）
A3: 姓名 | B3: 岗位 | C3: 分工 | D3: 量化块明细（70%） | E3: 任务块（30%）
A4: 金炜铮 | B4: 物流中心主管 | C4: 物流中心全范围 | D4: 团队单台成本30 · 三段结构20 · 团队请款10 · 专员均分10 | E4: 管理任务
A5: 郑舒漫 | B5: 物流专员 | C5: 头程FOB | D5: FOB(单证15+订舱10) · FCA执行25 · 请款20 | E5: 30
A6: 吴佳钒 | B6: 物流专员 | C6: 头程DDP | D6: DDP成本27+时效18 · 始发计划10 · 在途库存5 · 请款10 | E6: 30
A7: 黄婷 | B7: 物流专员 | C7: 目的国大货中转、B端运输 | D7: B端成本21+时效14 · 目的国计划10 · B端库存10 · 请款15 | E7: 30
A8: 吴定佳 | B8: 物流专员 | C8: 一件代发、C端履约、售后退货 | D8: 一件代发成本24+时效16 · 退件率10 · C端库存10 · 请款10 | E8: 30
A9: 张雨洁 | B9: 物流实习生 | C9: 样机发运、进口、账单核对 | D9: 特殊发运40 · 进口时效20 · 账单协同10（不排名不挂钱） | E9: 30

Sheet 指标标准
A1: 指标标准字典（唯一口径来源）
A3: 指标ID | B3: 人员 | C3: 业务线 | D3: 指标 | E3: 公式类型 | F3: 目标 | G3: 单位 | H3: 权重 | I3: 原始字段说明 | J3: 数据源 | K3: 取值口径
A4: K01 | B4: 吴佳钒 | C4: DDP头程 | D4: 成本 | E4: 成本-计算 | F4: 15 | G4: 欧/台 | H4: 27 | I4: 发货数量A / 运费折欧B | J4: 头程大表；长期易仓 | K4: 当月签收订单
A5: K02 | B5: 吴佳钒 | C5: DDP头程 | D5: 时效 | E5: 达标率 | G5: % | H5: 18 | I5: 达标单数 / 总单数 | J5: 头程大表；长期易仓 | K5: 当月签收订单，标准时效
A6: K03 | B6: 吴佳钒 | C6: 始发计划 | D6: 缺货率 | E6: 上限 | F6: 0.05 | G6: % | H6: 5 | I6: 实际缺货率(小数) | J6: 库内MES+排产表 | K6: 每周一交付计划
A7: K04 | B7: 吴佳钒 | C7: 始发计划 | D7: 缺货时间 | E7: 上限 | F7: 7 | G7: 天 | H7: 5 | I7: 实际缺货天数 | J7: 库内MES+排产表 | K7: 缺货持续≤7天
A8: K05 | B8: 吴佳钒 | C8: 在途库存 | D8: 上架准确率 | E8: 下限 | F8: 0.95 | G8: % | H8: 5 | I8: 实际上架准确率(小数) | J8: 各仓入库单上架情况
A9: K06 | B9: 吴佳钒 | C9: 财务 | D9: 请款-DDP | E9: 请款 | H9: 10 | I9: 迟报工作日数 / 请款金额占比(小数) | J9: 请款记录 | K9: 10号前，≥90%
A10: K07 | B10: 郑舒漫 | C10: FOB | D10: 单证准确率 | E10: 下限 | F10: 1 | G10: % | H10: 15 | I10: 单证准确率(小数) | J10: 货代台账 | K10: 我方单证零差错
A11: K08 | B11: 郑舒漫 | C11: FOB | D11: 订舱及时率 | E11: 达标率 | G11: % | H11: 10 | I11: 按时回传S/O单数 / 总单数 | J11: 货代台账 | K11: OA审单→S/O≤1个工作日
A12: K09 | B12: 郑舒漫 | C12: FCA | D12: 执行时效 | E12: 达标率 | G12: % | H12: 25 | I12: 48h内达标单数 / 总单数 | J12: OA订单数据 | K12: OA申请→工厂发出≤48h
A13: K10 | B13: 郑舒漫 | C13: 财务 | D13: 请款-FOB | E13: 请款 | H13: 20 | I13: 迟报工作日数 / 请款金额占比(小数) | J13: 请款记录 | K13: 10号前，≥90%
A14: K11 | B14: 黄婷 | C14: B端中转 | D14: 成本 | E14: 成本-计算 | F14: 15 | G14: 欧/台 | H14: 21 | I14: 签收数量A / 运费折欧B | J14: 当月核对账单 | K14: 当月签收
A15: K12 | B15: 黄婷 | C15: B端中转 | D15: 时效 | E15: 达标率 | G15: % | H15: 14 | I15: 达标单数 / 总单数 | J15: 签收单+分段标准 | K15: DE1/DK2/AT2/SE1/SI2工作日；旺3-6淡7-2
A16: K13 | B16: 黄婷 | C16: 目的国计划 | D16: 缺货率 | E16: 上限 | F16: 0.05 | G16: % | H16: 5 | I16: 实际缺货率(小数) | J16: 在库+待发+在途表 | K16: 每周一交付计划
A17: K14 | B17: 黄婷 | C17: 目的国计划 | D17: 缺货时间 | E17: 上限 | F17: 7 | G17: 天 | H17: 5 | I17: 实际缺货天数 | J17: 在库+待发+在途表 | K17: 缺货持续≤7天
A18: K15 | B18: 黄婷 | C18: B端库存 | D18: 综合 | E18: 库存综合 | H18: 10 | I18: 长周期占比(小数) / 平均库龄(天) / 单台库内成本(欧) | J18: 各仓库存表+账单 | K18: ≤3%/≤120天/≤5欧
A19: K16 | B19: 黄婷 | C19: 财务 | D19: 请款-B端仓库内 | E19: 请款 | H19: 7.5 | I19: 迟报工作日数 / 请款金额占比(小数) | J19: 请款记录 | K19: 10号前，≥90%
A20: K17 | B20: 黄婷 | C20: 财务 | D20: 请款-海外仓调拨 | E20: 请款 | H20: 7.5 | I20: 迟报工作日数 / 请款金额占比(小数) | J20: 请款记录 | K20: 10号前，≥90%
A21: K18 | B21: 吴定佳 | C21: 一件代发 | D21: 成本 | E21: 成本-计算 | F21: 15 | G21: 欧/台 | H21: 24 | I21: 出库数量A / 运费折欧B | J21: 正向仓账单+领星/易仓 | K21: 当月出库
A22: K19 | B22: 吴定佳 | C22: 一件代发 | D22: 时效 | E22: 达标率 | G22: % | H22: 16 | I22: 达标单数 / 总单数 | J22: 渠道承诺时效 | K22: 出库单生成→签收；分段标准任务块定稿
A23: K20 | B23: 吴定佳 | C23: 售后物流 | D23: 退件率 | E23: 上限 | F23: 0.02 | G23: % | H23: 10 | I23: 物流因素退件率(小数) | J23: 客服数据 | K23: ≤2%
A24: K21 | B24: 吴定佳 | C24: C端库存 | D24: 综合 | E24: 库存综合 | H24: 10 | I24: 长周期占比(小数) / 平均库龄(天) / 单台库内成本(欧) | J24: 各仓库存表+账单 | K24: ≤3%/≤120天/≤5欧
A25: K22 | B25: 吴定佳 | C25: 财务 | D25: 请款-C端仓库内 | E25: 请款 | H25: 10 | I25: 迟报工作日数 / 请款金额占比(小数) | J25: 请款记录 | K25: 10号前，≥90%
A26: K23 | B26: 张雨洁 | C26: 特殊发运 | D26: 时效 | E26: 达标率 | G26: % | H26: 40 | I26: 达标单数 / 总单数 | J26: 头程大表；长期易仓 | K26: 当月签收，按运输方式分段
A27: K24 | B27: 张雨洁 | C27: 进口业务 | D27: 时效 | E27: 达标率 | G27: % | H27: 20 | I27: 达标单数 / 总单数 | J27: 待定 | K27: 分段标准8月底前定，否则首月NA
A28: K25 | B28: 张雨洁 | C28: 财务 | D28: 账单协同-请款 | E28: 请款 | H28: 10 | I28: 迟报工作日数 / 请款金额占比(小数) | J28: 请款记录 | K28: 协同雨洁表格
A29: K26 | B29: 金炜铮 | C29: 团队 | D29: 单台总成本 | E29: 成本-直填 | F29: 36 | G29: 欧/台 | H29: 30 | I29: 当月实际单台总成本 | J29: 财务核算 | K29: 对齐降本分成方案结算线
A30: K27 | B30: 金炜铮 | C30: 团队 | D30: 三段结构 | E30: 三段综合 | H30: 20 | I30: 头程实际 / 尾程实际 / 仓储实际 | J30: 财务核算 | K30: 15/15/6，各段得分平均
A31: K28 | B31: 金炜铮 | C31: 团队 | D31: 团队请款及时率 | E31: 引用-请款均 | H31: 10 | J31: 全员请款线平均 | K31: 打分表内自动引用
A32: K29 | B32: 金炜铮 | C32: 团队 | D32: 专员均分 | E32: 引用-专员均分 | H32: 10 | J32: 4位专员总分平均 | K32: 打分表内自动引用

Sheet 打分表模板
A1: 绩效月份： | B1: 2026-09 | C1: 复制本表命名为 打分-YYYY-MM；数据不可得选NA；原始数据见[指标标准]字段说明
A3: 指标ID | B3: 人员 | C3: 业务线 | D3: 指标 | E3: 公式类型 | F3: 目标值 | G3: 单位 | H3: 数据可用 | I3: 原始1 | J3: 原始2 | K3: 原始3 | L3: 原始4 | M3: 指标得分 | N3: 全局权重 | O3: 有效权重 | P3: 加权分
A4: K01 | B4: 吴佳钒 | C4: DDP头程 | D4: 成本 | E4: 成本-计算 | F4: 15 | G4: 欧/台 | H4: 是 | M4: =IFERROR(IF($H4<>"是","",IF(OR($I4=0,$I4=""),"",MIN(100,100*$F4/($J4/$I4)))),"") | N4: 27 | O4: =IF(AND($H4="是",ISNUMBER($M4)),$N4,0) | P4: =IF(ISNUMBER($M4),$M4*$O4,0)
A5: K02 | B5: 吴佳钒 | C5: DDP头程 | D5: 时效 | E5: 达标率 | G5: % | H5: 是 | M5: =IFERROR(IF($H5<>"是","",IF(OR($J5=0,$J5=""),"",MIN(100,$I5/$J5*100))),"") | N5: 18 | O5: =IF(AND($H5="是",ISNUMBER($M5)),$N5,0) | P5: =IF(ISNUMBER($M5),$M5*$O5,0)
A6: K03 | B6: 吴佳钒 | C6: 始发计划 | D6: 缺货率 | E6: 上限 | F6: 0.05 | G6: % | H6: 是 | M6: =IFERROR(IF($H6<>"是","",IF($I6="","",IF($I6<=$F6,100,100*$F6/$I6))),"") | N6: 5 | O6: =IF(AND($H6="是",ISNUMBER($M6)),$N6,0) | P6: =IF(ISNUMBER($M6),$M6*$O6,0)
A7: K04 | B7: 吴佳钒 | C7: 始发计划 | D7: 缺货时间 | E7: 上限 | F7: 7 | G7: 天 | H7: 是 | M7: =IFERROR(IF($H7<>"是","",IF($I7="","",IF($I7<=$F7,100,100*$F7/$I7))),"") | N7: 5 | O7: =IF(AND($H7="是",ISNUMBER($M7)),$N7,0) | P7: =IF(ISNUMBER($M7),$M7*$O7,0)
A8: K05 | B8: 吴佳钒 | C8: 在途库存 | D8: 上架准确率 | E8: 下限 | F8: 0.95 | G8: % | H8: 是 | M8: =IFERROR(IF($H8<>"是","",IF($I8="","",IF($I8>=$F8,100,100*$I8/$F8))),"") | N8: 5 | O8: =IF(AND($H8="是",ISNUMBER($M8)),$N8,0) | P8: =IF(ISNUMBER($M8),$M8*$O8,0)
A9: K06 | B9: 吴佳钒 | C9: 财务 | D9: 请款-DDP | E9: 请款 | H9: 是 | M9: =IFERROR(IF($H9<>"是","",0.5*MAX(0,100-20*$I9)+0.5*MIN(100,$J9/0.9*100)),"") | N9: 10 | O9: =IF(AND($H9="是",ISNUMBER($M9)),$N9,0) | P9: =IF(ISNUMBER($M9),$M9*$O9,0)
A10: K07 | B10: 郑舒漫 | C10: FOB | D10: 单证准确率 | E10: 下限 | F10: 1 | G10: % | H10: 是 | M10: =IFERROR(IF($H10<>"是","",IF($I10="","",IF($I10>=$F10,100,100*$I10/$F10))),"") | N10: 15 | O10: =IF(AND($H10="是",ISNUMBER($M10)),$N10,0) | P10: =IF(ISNUMBER($M10),$M10*$O10,0)
A11: K08 | B11: 郑舒漫 | C11: FOB | D11: 订舱及时率 | E11: 达标率 | G11: % | H11: 是 | M11: =IFERROR(IF($H11<>"是","",IF(OR($J11=0,$J11=""),"",MIN(100,$I11/$J11*100))),"") | N11: 10 | O11: =IF(AND($H11="是",ISNUMBER($M11)),$N11,0) | P11: =IF(ISNUMBER($M11),$M11*$O11,0)
A12: K09 | B12: 郑舒漫 | C12: FCA | D12: 执行时效 | E12: 达标率 | G12: % | H12: 是 | M12: =IFERROR(IF($H12<>"是","",IF(OR($J12=0,$J12=""),"",MIN(100,$I12/$J12*100))),"") | N12: 25 | O12: =IF(AND($H12="是",ISNUMBER($M12)),$N12,0) | P12: =IF(ISNUMBER($M12),$M12*$O12,0)
A13: K10 | B13: 郑舒漫 | C13: 财务 | D13: 请款-FOB | E13: 请款 | H13: 是 | M13: =IFERROR(IF($H13<>"是","",0.5*MAX(0,100-20*$I13)+0.5*MIN(100,$J13/0.9*100)),"") | N13: 20 | O13: =IF(AND($H13="是",ISNUMBER($M13)),$N13,0) | P13: =IF(ISNUMBER($M13),$M13*$O13,0)
A14: K11 | B14: 黄婷 | C14: B端中转 | D14: 成本 | E14: 成本-计算 | F14: 15 | G14: 欧/台 | H14: 是 | M14: =IFERROR(IF($H14<>"是","",IF(OR($I14=0,$I14=""),"",MIN(100,100*$F14/($J14/$I14)))),"") | N14: 21 | O14: =IF(AND($H14="是",ISNUMBER($M14)),$N14,0) | P14: =IF(ISNUMBER($M14),$M14*$O14,0)
A15: K12 | B15: 黄婷 | C15: B端中转 | D15: 时效 | E15: 达标率 | G15: % | H15: 是 | M15: =IFERROR(IF($H15<>"是","",IF(OR($J15=0,$J15=""),"",MIN(100,$I15/$J15*100))),"") | N15: 14 | O15: =IF(AND($H15="是",ISNUMBER($M15)),$N15,0) | P15: =IF(ISNUMBER($M15),$M15*$O15,0)
A16: K13 | B16: 黄婷 | C16: 目的国计划 | D16: 缺货率 | E16: 上限 | F16: 0.05 | G16: % | H16: 是 | M16: =IFERROR(IF($H16<>"是","",IF($I16="","",IF($I16<=$F16,100,100*$F16/$I16))),"") | N16: 5 | O16: =IF(AND($H16="是",ISNUMBER($M16)),$N16,0) | P16: =IF(ISNUMBER($M16),$M16*$O16,0)
A17: K14 | B17: 黄婷 | C17: 目的国计划 | D17: 缺货时间 | E17: 上限 | F17: 7 | G17: 天 | H17: 是 | M17: =IFERROR(IF($H17<>"是","",IF($I17="","",IF($I17<=$F17,100,100*$F17/$I17))),"") | N17: 5 | O17: =IF(AND($H17="是",ISNUMBER($M17)),$N17,0) | P17: =IF(ISNUMBER($M17),$M17*$O17,0)
A18: K15 | B18: 黄婷 | C18: B端库存 | D18: 综合 | E18: 库存综合 | H18: 是 | M18: =IFERROR(IF($H18<>"是","",IFERROR(AVERAGE(IF($I18<=0.03,100,100*0.03/$I18),IF($J18<=120,100,100*120/$J18),IF($K18<=5,100,100*5/$K18)),"")),"") | N18: 10 | O18: =IF(AND($H18="是",ISNUMBER($M18)),$N18,0) | P18: =IF(ISNUMBER($M18),$M18*$O18,0)
A19: K16 | B19: 黄婷 | C19: 财务 | D19: 请款-B端仓库内 | E19: 请款 | H19: 是 | M19: =IFERROR(IF($H19<>"是","",0.5*MAX(0,100-20*$I19)+0.5*MIN(100,$J19/0.9*100)),"") | N19: 7.5 | O19: =IF(AND($H19="是",ISNUMBER($M19)),$N19,0) | P19: =IF(ISNUMBER($M19),$M19*$O19,0)
A20: K17 | B20: 黄婷 | C20: 财务 | D20: 请款-海外仓调拨 | E20: 请款 | H20: 是 | M20: =IFERROR(IF($H20<>"是","",0.5*MAX(0,100-20*$I20)+0.5*MIN(100,$J20/0.9*100)),"") | N20: 7.5 | O20: =IF(AND($H20="是",ISNUMBER($M20)),$N20,0) | P20: =IF(ISNUMBER($M20),$M20*$O20,0)
A21: K18 | B21: 吴定佳 | C21: 一件代发 | D21: 成本 | E21: 成本-计算 | F21: 15 | G21: 欧/台 | H21: 是 | M21: =IFERROR(IF($H21<>"是","",IF(OR($I21=0,$I21=""),"",MIN(100,100*$F21/($J21/$I21)))),"") | N21: 24 | O21: =IF(AND($H21="是",ISNUMBER($M21)),$N21,0) | P21: =IF(ISNUMBER($M21),$M21*$O21,0)
A22: K19 | B22: 吴定佳 | C22: 一件代发 | D22: 时效 | E22: 达标率 | G22: % | H22: 是 | M22: =IFERROR(IF($H22<>"是","",IF(OR($J22=0,$J22=""),"",MIN(100,$I22/$J22*100))),"") | N22: 16 | O22: =IF(AND($H22="是",ISNUMBER($M22)),$N22,0) | P22: =IF(ISNUMBER($M22),$M22*$O22,0)
A23: K20 | B23: 吴定佳 | C23: 售后物流 | D23: 退件率 | E23: 上限 | F23: 0.02 | G23: % | H23: 是 | M23: =IFERROR(IF($H23<>"是","",IF($I23="","",IF($I23<=$F23,100,100*$F23/$I23))),"") | N23: 10 | O23: =IF(AND($H23="是",ISNUMBER($M23)),$N23,0) | P23: =IF(ISNUMBER($M23),$M23*$O23,0)
A24: K21 | B24: 吴定佳 | C24: C端库存 | D24: 综合 | E24: 库存综合 | H24: 是 | M24: =IFERROR(IF($H24<>"是","",IFERROR(AVERAGE(IF($I24<=0.03,100,100*0.03/$I24),IF($J24<=120,100,100*120/$J24),IF($K24<=5,100,100*5/$K24)),"")),"") | N24: 10 | O24: =IF(AND($H24="是",ISNUMBER($M24)),$N24,0) | P24: =IF(ISNUMBER($M24),$M24*$O24,0)
A25: K22 | B25: 吴定佳 | C25: 财务 | D25: 请款-C端仓库内 | E25: 请款 | H25: 是 | M25: =IFERROR(IF($H25<>"是","",0.5*MAX(0,100-20*$I25)+0.5*MIN(100,$J25/0.9*100)),"") | N25: 10 | O25: =IF(AND($H25="是",ISNUMBER($M25)),$N25,0) | P25: =IF(ISNUMBER($M25),$M25*$O25,0)
A26: K23 | B26: 张雨洁 | C26: 特殊发运 | D26: 时效 | E26: 达标率 | G26: % | H26: 是 | M26: =IFERROR(IF($H26<>"是","",IF(OR($J26=0,$J26=""),"",MIN(100,$I26/$J26*100))),"") | N26: 40 | O26: =IF(AND($H26="是",ISNUMBER($M26)),$N26,0) | P26: =IF(ISNUMBER($M26),$M26*$O26,0)
A27: K24 | B27: 张雨洁 | C27: 进口业务 | D27: 时效 | E27: 达标率 | G27: % | H27: 是 | M27: =IFERROR(IF($H27<>"是","",IF(OR($J27=0,$J27=""),"",MIN(100,$I27/$J27*100))),"") | N27: 20 | O27: =IF(AND($H27="是",ISNUMBER($M27)),$N27,0) | P27: =IF(ISNUMBER($M27),$M27*$O27,0)
A28: K25 | B28: 张雨洁 | C28: 财务 | D28: 账单协同-请款 | E28: 请款 | H28: 是 | M28: =IFERROR(IF($H28<>"是","",0.5*MAX(0,100-20*$I28)+0.5*MIN(100,$J28/0.9*100)),"") | N28: 10 | O28: =IF(AND($H28="是",ISNUMBER($M28)),$N28,0) | P28: =IF(ISNUMBER($M28),$M28*$O28,0)
A29: K26 | B29: 金炜铮 | C29: 团队 | D29: 单台总成本 | E29: 成本-直填 | F29: 36 | G29: 欧/台 | H29: 是 | M29: =IFERROR(IF($H29<>"是","",IF($I29="","",MIN(100,100*$F29/$I29))),"") | N29: 30 | O29: =IF(AND($H29="是",ISNUMBER($M29)),$N29,0) | P29: =IF(ISNUMBER($M29),$M29*$O29,0)
A30: K27 | B30: 金炜铮 | C30: 团队 | D30: 三段结构 | E30: 三段综合 | H30: 是 | M30: =IFERROR(IF($H30<>"是","",IFERROR(AVERAGE(MIN(100,100*15/$I30),MIN(100,100*15/$J30),MIN(100,100*6/$K30)),"")),"") | N30: 20 | O30: =IF(AND($H30="是",ISNUMBER($M30)),$N30,0) | P30: =IF(ISNUMBER($M30),$M30*$O30,0)
A31: K28 | B31: 金炜铮 | C31: 团队 | D31: 团队请款及时率 | E31: 引用-请款均 | H31: 是 | M31: =IFERROR(IF($H31<>"是","",IFERROR(AVERAGE($M$9,$M$13,$M$19,$M$20,$M$25,$M$28),"")),"") | N31: 10 | O31: =IF(AND($H31="是",ISNUMBER($M31)),$N31,0) | P31: =IF(ISNUMBER($M31),$M31*$O31,0)
A32: K29 | B32: 金炜铮 | C32: 团队 | D32: 专员均分 | E32: 引用-专员均分 | H32: 是 | M32: =IFERROR(IF($H32<>"是","",IFERROR(AVERAGE($F$39:$F$42),"")),"") | N32: 10 | O32: =IF(AND($H32="是",ISNUMBER($M32)),$N32,0) | P32: =IF(ISNUMBER($M32),$M32*$O32,0)
A34: 监控区（不计分，只显示）——不可控但重要
A35: M01 | B35: 郑舒漫 | C35: FOB | D35: 截关装船准时率 | E35: 达标率 | H35: 是 | M35: =IF($H35<>"是","",IF(OR($J35=0,$J35=""),"",MIN(100,$I35/$J35*100))) | N35: —
A37: 个人总分区（自动计算）
A38: 人员 | B38: 量化有效权重和 | C38: 量化加权分和 | D38: 任务块得分 | E38: 数据覆盖率 | F38: 总分
A39: 吴佳钒 | B39: =SUM($O$4:$O$9) | C39: =SUM($P$4:$P$9) | D39: =IFERROR(AVERAGEIFS(任务块!$E:$E,任务块!$B:$B,$A39,任务块!$A:$A,$B$1),"") | E39: =B39/70 | F39: =IFERROR((C39+IF(ISNUMBER(D39),D39*30,0))/(B39+IF(ISNUMBER(D39),30,0)),"")
A40: 郑舒漫 | B40: =SUM($O$10:$O$13) | C40: =SUM($P$10:$P$13) | D40: =IFERROR(AVERAGEIFS(任务块!$E:$E,任务块!$B:$B,$A40,任务块!$A:$A,$B$1),"") | E40: =B40/70 | F40: =IFERROR((C40+IF(ISNUMBER(D40),D40*30,0))/(B40+IF(ISNUMBER(D40),30,0)),"")
A41: 黄婷 | B41: =SUM($O$14:$O$20) | C41: =SUM($P$14:$P$20) | D41: =IFERROR(AVERAGEIFS(任务块!$E:$E,任务块!$B:$B,$A41,任务块!$A:$A,$B$1),"") | E41: =B41/70 | F41: =IFERROR((C41+IF(ISNUMBER(D41),D41*30,0))/(B41+IF(ISNUMBER(D41),30,0)),"")
A42: 吴定佳 | B42: =SUM($O$21:$O$25) | C42: =SUM($P$21:$P$25) | D42: =IFERROR(AVERAGEIFS(任务块!$E:$E,任务块!$B:$B,$A42,任务块!$A:$A,$B$1),"") | E42: =B42/70 | F42: =IFERROR((C42+IF(ISNUMBER(D42),D42*30,0))/(B42+IF(ISNUMBER(D42),30,0)),"")
A43: 张雨洁 | B43: =SUM($O$26:$O$28) | C43: =SUM($P$26:$P$28) | D43: =IFERROR(AVERAGEIFS(任务块!$E:$E,任务块!$B:$B,$A43,任务块!$A:$A,$B$1),"") | E43: =B43/70 | F43: =IFERROR((C43+IF(ISNUMBER(D43),D43*30,0))/(B43+IF(ISNUMBER(D43),30,0)),"")
...

Sheet 任务块
A1: 任务块（每人每月3-5条，验收物必须可判定；0/50/100=未启动/进行中/完成）
A3: 月份 | B3: 姓名 | C3: 任务内容 | D3: 验收物 | E3: 得分
A4: 2026-09 | B4: 吴佳钒 | C4: DDP头程交接平稳 | D4: 当月零错发（头程大表核对）
A5: 2026-09 | B5: 吴佳钒 | C5: 易仓货件数据打通 | D5: 易仓导出口径文档+首月数据回填
A6: 2026-09 | B6: 郑舒漫 | C6: FOB货代台账上线 | D6: 台账含单证+订舱时效字段、近3个月数据
A7: 2026-09 | B7: 黄婷 | C7: B端库存三项指标基线摸底 | D7: 各仓长周期/库龄/库内成本基线表
A8: 2026-09 | B8: 吴定佳 | C8: 一件代发时效分段标准定稿 | D8: 打包/运输分段标准文档，主管签认
A9: 2026-09 | B9: 张雨洁 | C9: 进口时效分段标准整理 | D9: 分段标准表（无现成标准则注明NA）
A10: 2026-09 | B10: 金炜铮 | C10: 绩效体系首月跑通+复盘 | D10: 首月记分卡+看板产出+修订清单
